[2024-12-13T13:19:45.324+0000] {taskinstance.py:1103} INFO - Dependencies all met for dep_context=non-requeueable deps ti=<TaskInstance: transform_dag.transform_data_task manual__2024-12-13T13:19:42.889139+00:00 [queued]>
[2024-12-13T13:19:45.328+0000] {taskinstance.py:1103} INFO - Dependencies all met for dep_context=requeueable deps ti=<TaskInstance: transform_dag.transform_data_task manual__2024-12-13T13:19:42.889139+00:00 [queued]>
[2024-12-13T13:19:45.328+0000] {taskinstance.py:1308} INFO - Starting attempt 1 of 1
[2024-12-13T13:19:45.338+0000] {taskinstance.py:1327} INFO - Executing <Task(PythonOperator): transform_data_task> on 2024-12-13 13:19:42.889139+00:00
[2024-12-13T13:19:45.341+0000] {standard_task_runner.py:57} INFO - Started process 33709 to run task
[2024-12-13T13:19:45.343+0000] {standard_task_runner.py:84} INFO - Running: ['airflow', 'tasks', 'run', 'transform_dag', 'transform_data_task', 'manual__2024-12-13T13:19:42.889139+00:00', '--job-id', '18', '--raw', '--subdir', 'DAGS_FOLDER/transform_dag.py', '--cfg-path', '/tmp/tmp7z0djjj4']
[2024-12-13T13:19:45.344+0000] {standard_task_runner.py:85} INFO - Job 18: Subtask transform_data_task
[2024-12-13T13:19:45.368+0000] {task_command.py:410} INFO - Running <TaskInstance: transform_dag.transform_data_task manual__2024-12-13T13:19:42.889139+00:00 [running]> on host codespaces-586565
[2024-12-13T13:19:45.400+0000] {taskinstance.py:1545} INFO - Exporting env vars: AIRFLOW_CTX_DAG_OWNER='airflow' AIRFLOW_CTX_DAG_ID='transform_dag' AIRFLOW_CTX_TASK_ID='transform_data_task' AIRFLOW_CTX_EXECUTION_DATE='2024-12-13T13:19:42.889139+00:00' AIRFLOW_CTX_TRY_NUMBER='1' AIRFLOW_CTX_DAG_RUN_ID='manual__2024-12-13T13:19:42.889139+00:00'
[2024-12-13T13:19:45.402+0000] {taskinstance.py:1824} ERROR - Task failed with exception
Traceback (most recent call last):
  File "/home/vscode/.local/lib/python3.10/site-packages/airflow/operators/python.py", line 181, in execute
    return_value = self.execute_callable()
  File "/home/vscode/.local/lib/python3.10/site-packages/airflow/operators/python.py", line 198, in execute_callable
    return self.python_callable(*self.op_args, **self.op_kwargs)
  File "/workspaces/hands-on-introduction-data-engineering-4395021/airflow/dags/transform_dag.py", line 12, in transform_data
    df = pd.read_csv('/path/to/manual-extract-data.csv')
  File "/home/vscode/.local/lib/python3.10/site-packages/pandas/io/parsers/readers.py", line 1026, in read_csv
    return _read(filepath_or_buffer, kwds)
  File "/home/vscode/.local/lib/python3.10/site-packages/pandas/io/parsers/readers.py", line 620, in _read
    parser = TextFileReader(filepath_or_buffer, **kwds)
  File "/home/vscode/.local/lib/python3.10/site-packages/pandas/io/parsers/readers.py", line 1620, in __init__
    self._engine = self._make_engine(f, self.engine)
  File "/home/vscode/.local/lib/python3.10/site-packages/pandas/io/parsers/readers.py", line 1880, in _make_engine
    self.handles = get_handle(
  File "/home/vscode/.local/lib/python3.10/site-packages/pandas/io/common.py", line 873, in get_handle
    handle = open(
FileNotFoundError: [Errno 2] No such file or directory: '/path/to/manual-extract-data.csv'
[2024-12-13T13:19:45.405+0000] {taskinstance.py:1345} INFO - Marking task as FAILED. dag_id=transform_dag, task_id=transform_data_task, execution_date=20241213T131942, start_date=20241213T131945, end_date=20241213T131945
[2024-12-13T13:19:45.414+0000] {standard_task_runner.py:104} ERROR - Failed to execute job 18 for task transform_data_task ([Errno 2] No such file or directory: '/path/to/manual-extract-data.csv'; 33709)
[2024-12-13T13:19:45.434+0000] {local_task_job_runner.py:225} INFO - Task exited with return code 1
[2024-12-13T13:19:45.442+0000] {taskinstance.py:2653} INFO - 0 downstream tasks scheduled from follow-on schedule check
